Client connected
message handler error
Traceback (most recent call last):
  File "/home/runner/workspace/.pythonlibs/lib/python3.11/site-packages/flask_socketio/__init__.py", line 829, in _handle_event
    ret = handler(auth)
          ^^^^^^^^^^^^^
TypeError: handle_connect() takes 0 positional arguments but 1 was given

During handling of the above exception, another exception occurred:

Traceback (most recent call last):
  File "/home/runner/workspace/.pythonlibs/lib/python3.11/site-packages/engineio/server.py", line 434, in run_handler
    return self.handlers[event](*args)
           ^^^^^^^^^^^^^^^^^^^^^^^^^^^
  File "/home/runner/workspace/.pythonlibs/lib/python3.11/site-packages/socketio/server.py", line 643, in _handle_eio_message
    self._handle_connect(eio_sid, pkt.namespace, pkt.data)
  File "/home/runner/workspace/.pythonlibs/lib/python3.11/site-packages/socketio/server.py", line 537, in _handle_connect
    success = self._trigger_event(
              ^^^^^^^^^^^^^^^^^^^^
  File "/home/runner/workspace/.pythonlibs/lib/python3.11/site-packages/socketio/server.py", line 614, in _trigger_event
    return handler(*args)
           ^^^^^^^^^^^^^^
  File "/home/runner/workspace/.pythonlibs/lib/python3.11/site-packages/flask_socketio/__init__.py", line 288, in _handler
    return self._handle_event(handler, message, real_ns, sid,
           ^^^^^^^^^^^^^^^^^^^^^^^^^^^^^^^^^^^^^^^^^^^^^^^^^^
  File "/home/runner/workspace/.pythonlibs/lib/python3.11/site-packages/flask_socketio/__init__.py", line 831, in _handle_event
    ret = handler()
          ^^^^^^^^^
  File "/home/runner/workspace/backend/app.py", line 26, in handle_connect
    emit('user_list', list(connected_users), broadcast=True)
    ^^^^
NameError: name 'emit' is not defined
172.31.196.156 - - [27/Sep/2024 19:54:41] "POST /socket.io/?EIO=4&transport=polling&t=P8r3C6v&sid=Tj8aMVKP8q0S_b8eAAAA HTTP/1.1" 200 -
172.31.196.156 - - [27/Sep/2024 19:54:42] "GET /socket.io/?EIO=4&transport=polling&t=P8r3C6w&sid=Tj8aMVKP8q0S_b8eAAAA HTTP/1.1" 200 -
